Workbook

Sheet Ringkasan
B1: RINGKASAN — RENCANA PERNIKAHAN
B2: Semua angka Rupiah. Ubah di sheet Budget → ringkasan & grafik ikut berubah.
B4: Total anggaran | C4: =Budget!E53 | E4: Saldo Blugether (Sep 2026) | F4: 50000000
B5: Sudah dibayar | C5: =Budget!E54 | E5: Menabung / bulan | F5: 5000000
B6: Sisa | C6: =Budget!E53-Budget!E54 | E6: Bulan s/d nikah (Syawal ±Apr 2028) | F6: 18
B7: Beban Blugether | C7: =SUMIF(Budget!G4:G51,"Blugether",Budget!E4:E51) | E7: Kapasitas Blugether s/d nikah | F7: =F4+F5*F6
B8: Beban Orang tua | C8: =SUMIF(Budget!G4:G51,"Ortu*",Budget!E4:E51)+SUMIF(Budget!G4:G51,"Lainnya",Budget!E4:E51) | E8: Saran kontribusi orang tua (min) | F8: =MAX(0,C6-F7)
B10: Anggaran per kategori | E10: Status pembayaran
B11: Kategori | C11: Total | E11: Status | F11: Total
B12: Lamaran | C12: =SUMIF(Budget!B4:B51,B12,Budget!E4:E51) | E12: Lunas | F12: =SUMIF(Budget!F4:F51,E12,Budget!E4:E51)
B13: Siraman | C13: =SUMIF(Budget!B4:B51,B13,Budget!E4:E51) | E13: DP dibayar | F13: =SUMIF(Budget!F4:F51,E13,Budget!E4:E51)
B14: Akad & Adat | C14: =SUMIF(Budget!B4:B51,B14,Budget!E4:E51) | E14: Belum | F14: =SUMIF(Budget!F4:F51,E14,Budget!E4:E51)
B15: Venue & F&B | C15: =SUMIF(Budget!B4:B51,B15,Budget!E4:E51)
B16: Resepsi & Dekor | C16: =SUMIF(Budget!B4:B51,B16,Budget!E4:E51) | E16: Siapa membayar
B17: Hiburan & Teknis | C17: =SUMIF(Budget!B4:B51,B17,Budget!E4:E51) | E17: Pembayar | F17: Total
B18: Busana, Rias & Rambut | C18: =SUMIF(Budget!B4:B51,B18,Budget!E4:E51) | E18: Blugether | F18: =SUMIF(Budget!G4:G51,"Blugether",Budget!E4:E51)
B19: Dokumentasi | C19: =SUMIF(Budget!B4:B51,B19,Budget!E4:E51) | E19: Orang tua | F19: =SUMIF(Budget!G4:G51,"Ortu*",Budget!E4:E51)
B20: Cincin & Pribadi | C20: =SUMIF(Budget!B4:B51,B20,Budget!E4:E51) | E20: Lainnya | F20: =SUMIF(Budget!G4:G51,"Lainnya",Budget!E4:E51)
B21: Souvenir & Tamu | C21: =SUMIF(Budget!B4:B51,B21,Budget!E4:E51)
B22: Logistik & Keluarga | C22: =SUMIF(Budget!B4:B51,B22,Budget!E4:E51)
B23: Cadangan | C23: =SUMIF(Budget!B4:B51,B23,Budget!E4:E51)

Sheet Budget
A1: BUDGET PERNIKAHAN — [ Mempelai Wanita ] & [ Mempelai Pria ]
A2: Adat Jawa · The Bimasena (Rooang), Dharmawangsa · semua angka Rupiah · sel putih bisa diedit
A3: No | B3: Kategori | C3: Item | D3: Qty / Pax | E3: Biaya | F3: Status | G3: Dibayar oleh | H3: Catatan
A4: 1 | B4: Lamaran | C4: Tenda + kursi (sewa) | E4: 1500000 | F4: Belum | G4: Blugether | H4: Di rumah mempelai wanita
A5: 2 | B5: Lamaran | C5: Dekorasi & bunga | E5: 1500000 | F5: Belum | G5: Blugether
A6: 3 | B6: Lamaran | C6: Makanan & minuman | E6: 1000000 | F6: Belum | G6: Blugether | H6: Masak sendiri di rumah
A7: 4 | B7: Lamaran | C7: Seserahan / hantaran | E7: 500000 | F7: Belum | G7: Blugether | H7: Nampan + wrapping
A8: 5 | B8: Lamaran | C8: Dokumentasi lamaran | D8: ½ hari | E8: 300000 | F8: Belum | G8: Blugether
A9: 6 | B9: Lamaran | C9: Makeup mempelai wanita (lamaran) | E9: 2000000 | F9: DP dibayar | G9: Blugether | H9: DP sudah dibayar
A10: 7 | B10: Lamaran | C10: Buffer lamaran | E10: 200000 | F10: Belum | G10: Blugether
A11: 8 | B11: Siraman | C11: Upacara siraman | E11: 3000000 | F11: Belum | G11: Blugether | H11: Bunga setaman, air 7 sumber, kendi, dawet, tumpeng
A12: 9 | B12: Siraman | C12: Katering keluarga (siraman) | E12: 1500000 | F12: Belum | G12: Ortu Wanita | H12: Makan keluarga di rumah
A13: 10 | B13: Siraman | C13: Lulur & henna pengantin | E13: 1500000 | F13: Belum | G13: Blugether
A14: 11 | B14: Akad & Adat | C14: Perlengkapan panggih (temu manten) | E14: 2000000 | F14: Belum | G14: Blugether | H14: Kembar mayang ×2, suruh, telur, kacar-kucur, sindur
A15: 12 | B15: Akad & Adat | C15: Hadroh / rebana (akad) | E15: 3000000 | F15: Belum | G15: Ortu Pria
A16: 13 | B16: Akad & Adat | C16: Penghulu / KUA (akad) | E16: 600000 | F16: Belum | G16: Blugether | H16: Di luar jam kantor
A17: 14 | B17: Akad & Adat | C17: Mahar + replika mahar | E17: 1200000 | F17: Belum | G17: Blugether | H17: Simbolis
A18: 15 | B18: Akad & Adat | C18: Medical check-up (syarat nikah) | D18: 2 org | E18: 1000000 | F18: Belum | G18: Blugether
A19: 16 | B19: Venue & F&B | C19: The Bimasena (Rooang) — minimum spending | D19: 100+ pax | E19: 150000000 | F19: Belum | G19: Blugether | H19: Min. spend; sudah termasuk F&B 100+ pax
A20: 17 | B20: Venue & F&B | C20: Tambahan pax / upgrade menu | E20: 0 | F20: Belum | G20: Blugether | H20: Isi bila melebihi minimum
A21: 18 | B21: Venue & F&B | C21: Makan vendor & panitia | E21: 3000000 | F21: Belum | G21: Blugether
A22: 19 | B22: Resepsi & Dekor | C22: Dekorasi & bunga resepsi | E22: 12000000 | F22: Belum | G22: Blugether | H22: Melati putih: pelaminan, entrance, aisle, meja
A23: 20 | B23: Resepsi & Dekor | C23: Bridal bouquet + melati groom & bride | E23: 2000000 | F23: Belum | G23: Blugether
A24: 21 | B24: Resepsi & Dekor | C24: Karpet (bila perlu) | E24: 0 | F24: Belum | G24: Blugether
A25: 22 | B25: Hiburan & Teknis | C25: Live music / band | E25: 8000000 | F25: Belum | G25: Blugether | H25: Akustik → band
A26: 23 | B26: Hiburan & Teknis | C26: MC / pranatacara | E26: 4000000 | F26: Belum | G26: Blugether | H26: Bilingual
A27: 24 | B27: Hiburan & Teknis | C27: Koordinator hari-H (WO on-the-day) | E27: 5000000 | F27: Belum | G27: Blugether | H27: Jaga rundown, cue vendor
A28: 25 | B28: Hiburan & Teknis | C28: Sound system & lighting | E28: 5000000 | F28: Belum | G28: Blugether | H28: Bila belum termasuk venue
A29: 26 | B29: Hiburan & Teknis | C29: Live streaming | E29: 3000000 | F29: Belum | G29: Blugether | H29: Opsional
A30: 27 | B30: Busana, Rias & Rambut | C30: Busana & rias mempelai wanita | E30: 18000000 | F30: Belum | G30: Blugether | H30: Paes ageng: siraman, akad, resepsi
A31: 28 | B31: Busana, Rias & Rambut | C31: Hairdo mempelai wanita | E31: 2000000 | F31: Belum | G31: Blugether
A32: 29 | B32: Busana, Rias & Rambut | C32: Sewa beskap mempelai pria (akad) | E32: 4000000 | F32: Belum | G32: Blugether | H32: Hanya beskap akad; tak perlu jas lamaran/resepsi
A33: 30 | B33: Busana, Rias & Rambut | C33: Busana adat orang tua | E33: 4000000 | F33: Belum | G33: Ortu | H33: Kebaya / beskap
A34: 31 | B34: Busana, Rias & Rambut | C34: Makeup orang tua & keluarga inti | E34: 4000000 | F34: Belum | G34: Ortu
A35: 32 | B35: Busana, Rias & Rambut | C35: Seragam panitia / keluarga | D35: ± 20 org | E35: 5000000 | F35: Belum | G35: Blugether | H35: ± 20 × 250rb
A36: 33 | B36: Busana, Rias & Rambut | C36: Accessories (mahkota, printilan) | E36: 3000000 | F36: Belum | G36: Blugether
A37: 34 | B37: Dokumentasi | C37: Foto & video (2 hari) | D37: siraman + hari-H | E37: 12000000 | F37: Belum | G37: Blugether
A38: 35 | B38: Dokumentasi | C38: Foto prewedding | E38: 3000000 | F38: Belum | G38: Blugether | H38: Opsional
A39: 36 | B39: Cincin & Pribadi | C39: Cincin tunangan + cincin nikah | E39: 23000000 | F39: Lunas | G39: Blugether | H39: Total kedua cincin — sudah dibeli
A40: 37 | B40: Cincin & Pribadi | C40: Hair care / perawatan pengantin | E40: 1500000 | F40: Belum | G40: Blugether
...

Sheet Timeline
B1: TIMELINE MENABUNG
B2: Tabungan kumulatif vs beban Blugether. Ubah saldo & tabungan di sheet Ringkasan.
B4: Bulan | C4: Tabungan kumulatif | D4: Beban Blugether | E4: Total anggaran
B5: Sep 2026 | C5: =Ringkasan!$F$4+Ringkasan!$F$5*0 | D5: =Ringkasan!$C$7 | E5: =Budget!$E$53
B6: Okt 2026 | C6: =Ringkasan!$F$4+Ringkasan!$F$5*1 | D6: =Ringkasan!$C$7 | E6: =Budget!$E$53
B7: Nov 2026 | C7: =Ringkasan!$F$4+Ringkasan!$F$5*2 | D7: =Ringkasan!$C$7 | E7: =Budget!$E$53
B8: Des 2026 | C8: =Ringkasan!$F$4+Ringkasan!$F$5*3 | D8: =Ringkasan!$C$7 | E8: =Budget!$E$53
B9: Jan 2027 | C9: =Ringkasan!$F$4+Ringkasan!$F$5*4 | D9: =Ringkasan!$C$7 | E9: =Budget!$E$53
B10: Feb 2027 | C10: =Ringkasan!$F$4+Ringkasan!$F$5*5 | D10: =Ringkasan!$C$7 | E10: =Budget!$E$53
B11: Mar 2027 | C11: =Ringkasan!$F$4+Ringkasan!$F$5*6 | D11: =Ringkasan!$C$7 | E11: =Budget!$E$53
B12: Apr 2027 | C12: =Ringkasan!$F$4+Ringkasan!$F$5*7 | D12: =Ringkasan!$C$7 | E12: =Budget!$E$53
B13: Mei 2027 | C13: =Ringkasan!$F$4+Ringkasan!$F$5*8 | D13: =Ringkasan!$C$7 | E13: =Budget!$E$53
B14: Jun 2027 | C14: =Ringkasan!$F$4+Ringkasan!$F$5*9 | D14: =Ringkasan!$C$7 | E14: =Budget!$E$53
B15: Jul 2027 | C15: =Ringkasan!$F$4+Ringkasan!$F$5*10 | D15: =Ringkasan!$C$7 | E15: =Budget!$E$53
B16: Agu 2027 | C16: =Ringkasan!$F$4+Ringkasan!$F$5*11 | D16: =Ringkasan!$C$7 | E16: =Budget!$E$53
B17: Sep 2027 | C17: =Ringkasan!$F$4+Ringkasan!$F$5*12 | D17: =Ringkasan!$C$7 | E17: =Budget!$E$53
B18: Okt 2027 | C18: =Ringkasan!$F$4+Ringkasan!$F$5*13 | D18: =Ringkasan!$C$7 | E18: =Budget!$E$53
B19: Nov 2027 | C19: =Ringkasan!$F$4+Ringkasan!$F$5*14 | D19: =Ringkasan!$C$7 | E19: =Budget!$E$53
B20: Des 2027 | C20: =Ringkasan!$F$4+Ringkasan!$F$5*15 | D20: =Ringkasan!$C$7 | E20: =Budget!$E$53
B21: Jan 2028 | C21: =Ringkasan!$F$4+Ringkasan!$F$5*16 | D21: =Ringkasan!$C$7 | E21: =Budget!$E$53
B22: Feb 2028 | C22: =Ringkasan!$F$4+Ringkasan!$F$5*17 | D22: =Ringkasan!$C$7 | E22: =Budget!$E$53
B23: Mar 2028 | C23: =Ringkasan!$F$4+Ringkasan!$F$5*18 | D23: =Ringkasan!$C$7 | E23: =Budget!$E$53
B24: Apr 2028 | C24: =Ringkasan!$F$4+Ringkasan!$F$5*19 | D24: =Ringkasan!$C$7 | E24: =Budget!$E$53
B25: Mei 2028 | C25: =Ringkasan!$F$4+Ringkasan!$F$5*20 | D25: =Ringkasan!$C$7 | E25: =Budget!$E$53
B26: Jun 2028 | C26: =Ringkasan!$F$4+Ringkasan!$F$5*21 | D26: =Ringkasan!$C$7 | E26: =Budget!$E$53
B27: Jul 2028 | C27: =Ringkasan!$F$4+Ringkasan!$F$5*22 | D27: =Ringkasan!$C$7 | E27: =Budget!$E$53
B28: Agu 2028 | C28: =Ringkasan!$F$4+Ringkasan!$F$5*23 | D28: =Ringkasan!$C$7 | E28: =Budget!$E$53
B29: Sep 2028 | C29: =Ringkasan!$F$4+Ringkasan!$F$5*24 | D29: =Ringkasan!$C$7 | E29: =Budget!$E$53
B30: Okt 2028 | C30: =Ringkasan!$F$4+Ringkasan!$F$5*25 | D30: =Ringkasan!$C$7 | E30: =Budget!$E$53
B31: Nov 2028 | C31: =Ringkasan!$F$4+Ringkasan!$F$5*26 | D31: =Ringkasan!$C$7 | E31: =Budget!$E$53
B32: Des 2028 | C32: =Ringkasan!$F$4+Ringkasan!$F$5*27 | D32: =Ringkasan!$C$7 | E32: =Budget!$E$53
E35: Milestone
E36: November 2026 | F36: Lamaran / tunangan
E37: H-1 pernikahan | F37: Siraman
E38: ± April 2028 | F38: Akad & resepsi — Syawal 1449 H
